I'm sorry, but an uncaught exception occurred.

While running game code:
  File "game/script.rpy", line 31, in script
    scene bg nargothrond
Exception: Image 'bg' does not accept attributes 'nargothrond'.

-- Full Traceback ------------------------------------------------------------

Full traceback:
  File "game/script.rpy", line 31, in script
    scene bg nargothrond
  File "C:\Users\Jon\Downloads\renpy\renpy-8.2.1-sdk\renpy\ast.py", line 1247, in execute
    show_imspec(self.imspec, atl=getattr(self, "atl", None))
  File "C:\Users\Jon\Downloads\renpy\renpy-8.2.1-sdk\renpy\ast.py", line 1076, in show_imspec
    renpy.config.show(name,
  File "C:\Users\Jon\Downloads\renpy\renpy-8.2.1-sdk\renpy\exports.py", line 739, in show
    if not base.find_target() and renpy.config.missing_show:
  File "C:\Users\Jon\Downloads\renpy\renpy-8.2.1-sdk\renpy\display\image.py", line 421, in find_target
    self.target = target._duplicate(a)
  File "C:\Users\Jon\Downloads\renpy\renpy-8.2.1-sdk\renpy\display\displayable.py", line 246, in _duplicate
    args.extraneous()
  File "C:\Users\Jon\Downloads\renpy\renpy-8.2.1-sdk\renpy\display\displayable.py", line 109, in extraneous
    raise Exception("Image '{}' does not accept attributes '{}'.".format(
Exception: Image 'bg' does not accept attributes 'nargothrond'.

Windows-10-10.0.19045 AMD64
Ren'Py 8.2.1.24030407
testprojectrepny 1.0
Wed May  8 23:41:03 2024
